<?xml version="1.0" ?>
<robot name="mbot">

    <link name="base_link">
        <visual>
            <origin xyz=" 0 0 0" rpy="0 0 0" />
            <geometry>
                <cylinder length="0.16" radius="0.20"/>
            </geometry>
            <material name="yellow">
                <color rgba="1 0.4 0 1"/>
            </material>
        </visual>
    </link>

   <link name="arm_link0">
        <visual>
            <origin xyz=" 0 0 0.03" rpy="0 0 0" />
            <geometry>
                <cylinder length="0.06" radius="0.05"/>
            </geometry>
            <material name="arm_color">
                <color rgba="0.5 1 0.5 1"/>
            </material>
        </visual>
    </link>

    <joint name="arm_joint0" type="continuous">
        <origin xyz="0 0 0.08" rpy="0 0 0"/>
        <parent link="base_link"/>
        <child link="arm_link0"/>
        <axis xyz="0 0 1"/>
    </joint>

   <link name="arm_link1_1">
        <visual>
            <origin xyz=" 0 0 0.04" rpy="1.5707 0 0" />
            <geometry>
                <cylinder length="0.05" radius="0.04"/>
            </geometry>
            <material name="arm_color">
                <color rgba="0.5 1 0.5 1"/>
            </material>
        </visual>
    </link>

    <joint name="arm_joint1_1" type="continuous">
        <origin xyz="0 0 0.06" rpy="0 0 0"/>
        <parent link="arm_link0"/>
        <child link="arm_link1_1"/>
        <axis xyz="0 1 0"/>
    </joint>

   <link name="arm_link1_2">
        <visual>
            <origin xyz=" 0 0 0.06" rpy="1.5707 0 0" />
            <geometry>
                <box size= "0.08 0.12 0.05" />
            </geometry>
            <material name="arm_color">
                <color rgba="0.5 1 0.5 1"/>
            </material>
        </visual>
    </link>

    <joint name="arm_joint1_2" type="fixed">
        <origin xyz="0 0 0.04" rpy="0 0 0"/>
        <parent link="arm_link1_1"/>
        <child link="arm_link1_2"/>
    </joint>

   <link name="arm_link1_3">
        <visual>
            <origin xyz=" 0 0 0" rpy="1.5707 0 0" />
            <geometry>
                <cylinder length="0.05" radius="0.04"/>
            </geometry>
            <material name="arm_color">
                <color rgba="0.5 1 0.5 1"/>
            </material>
        </visual>
    </link>

    <joint name="arm_joint1_3" type="continuous">
        <origin xyz="0 0 0.12" rpy="0 0 0"/>
        <parent link="arm_link1_2"/>
        <child link="arm_link1_3"/>
        <axis xyz="0 1 0"/>
    </joint>

   <link name="arm_link2_2">
        <visual>
            <origin xyz=" 0.06 0 0" rpy="0 0 0" />
            <geometry>
                <box size="0.12 0.05 0.08"/>
            </geometry>
            <material name="arm_color">
                <color rgba="0.5 1 0.5 1"/>
            </material>
        </visual>
    </link>

    <joint name="arm_joint2_2" type="fixed">
        <origin xyz="0 0 0" rpy="0 0 0"/>
        <parent link="arm_link1_3"/>
        <child link="arm_link2_2"/>
    </joint>

    <joint name="left_wheel_joint" type="continuous">
        <origin xyz="0 0.19 -0.05" rpy="0 0 0"/>
        <parent link="base_link"/>
        <child link="left_wheel_link"/>
        <axis xyz="0 1 0"/>
    </joint>

    <link name="left_wheel_link">
        <visual>
            <origin xyz="0 0 0" rpy="1.5707 0 0" />
            <geometry>
                <cylinder radius="0.06" length = "0.025"/>
            </geometry>
            <material name="white">
                <color rgba="1 1 1 0.9"/>
            </material>
        </visual>
    </link>

    <joint name="right_wheel_joint" type="continuous">
        <origin xyz="0 -0.19 -0.05" rpy="0 0 0"/>
        <parent link="base_link"/>
        <child link="right_wheel_link"/>
        <axis xyz="0 1 0"/>
    </joint>

    <link name="right_wheel_link">
        <visual>
            <origin xyz="0 0 0" rpy="1.5707 0 0" />
            <geometry>
                <cylinder radius="0.06" length = "0.025"/>
            </geometry>
            <material name="white">
                <color rgba="1 1 1 0.9"/>
            </material>
        </visual>
    </link>

    <joint name="front_caster_joint" type="continuous">
        <origin xyz="0.18 0 -0.095" rpy="0 0 0"/>
        <parent link="base_link"/>
        <child link="front_caster_link"/>
        <axis xyz="0 1 0"/>
    </joint>

    <link name="front_caster_link">
        <visual>
            <origin xyz="0 0 0" rpy="0 0 0"/>
            <geometry>
                <sphere radius="0.015" />
            </geometry>
            <material name="black">
                <color rgba="0 0 0 0.95"/>
            </material>
        </visual>
    </link>

    <joint name="back_caster_joint" type="continuous">
        <origin xyz="-0.18 0 -0.095" rpy="0 0 0"/>
        <parent link="base_link"/>
        <child link="back_caster_link"/>
        <axis xyz="0 1 0"/>
    </joint>

    <link name="back_caster_link">
        <visual>
            <origin xyz="0 0 0" rpy="0 0 0"/>
            <geometry>
                <sphere radius="0.015" />
            </geometry>
            <material name="black">
                <color rgba="0 0 0 0.95"/>
            </material>
        </visual>
    </link>

    <link name="kinect_link">
        <visual>
            <origin xyz="0 0 0" rpy="0 0 1.5708"/>
            <geometry>
                <mesh filename="package://mbot_description/meshes/kinect.dae" />
            </geometry>
        </visual>
    </link>

    <joint name="laser_joint" type="fixed">
        <origin xyz="0.15 0 0.11" rpy="0 0 0"/>
        <parent link="base_link"/>
        <child link="kinect_link"/>
    </joint>

</robot>
